Workbook

Sheet a remplir
B1: nom | C1: Consultant Christian | K1: Abonnement Transport en commun / mois
K2: Montant Internet par mois
B3: mois | K3: Montant Téléphone Par mois
K4: Autres / mois
B5: Nombre de jours travaillés facturés | H5: =+H9*12 -> 120 | J5: forfait repas (à la journée) | K5: ind km (à la journée) | L5: autres frais annuels | M5: frais refacturés aux clients annuel
B6: Nombre de jours ouvrés dans le mois | H6: 228 | I6: montant | K6: =+IF(IK!G72<>0,IK!G72,0) -> 34.19136 | L6: =+((L1/2)*12)+((L2/2)*12)+((L3/2)*12)+L4*12 -> 0
B7: Nombre de jours par semaine | H7: 5
B8: salaire de base | H8: 2374
B9: Simu mensuelle nombre de jours par mois | H9: 10
B10: Ticket Restaurant Annuel | E10: non | H10: =IF(E10="oui",H5,0) -> 0
B11: Ticket Restaurant Mensuel | H11: 19
B12: Valeur Faciale TR | H12: 14.36
B13: Prise en charge employeur | H13: 0.5
B15: Mutuelle | E15: oui | H15: =IF(E15="non",0,"1,5%") -> 1,5%
B16: PMSS | H16: 3925
B17: Tx mutuelle part salariale | H17: 0.5
B18: Tx mutuelle part patronale | H18: 0.5
B20: TJM | H20: 1000
C21: -Frais de gestion | H21: 0.05 | P21: Type de Véhicule | Q21: Voiture Thermique
C22: -Frais d intermediation | E22: montant par jour | H22: 0 | P22: Puissance FISCALE | Q22: 5
H23: ANNUEL | K23: MOIS | P23: Distance par jour Aller-retour en KM | Q23: =44.8*2 -> 89.6
P24: Nombre de déplacements par semaine | Q24: 3
B25: TJM | H25: =H20 -> 1000 | K25: =+H20 -> 1000
B26: Total mensuel | H26: =(H5*H20) -> 120000 | K26: =+H20*H9 -> 10000
C27: -Frais refacturés aux clients | H27: =M6 -> 0 | K27: =+H27/12 -> 0
F28: total | H28: =H27+H26 -> 120000 | K28: =K27+K26 -> 10000
C29: -Frais de gestion | F29: =H21 -> 0.05 | H29: =H28*F29 -> 6000 | K29: =+K26*H21 -> 500
C30: -Frais d intermediation | H30: =H22*H5 -> 0 | K30: =+H22*H9 -> 0
C31: - Frais de fonctionnement | H31: =H5*(J6+K6)+L6+M6 -> 4102.9632 | K31: =H31/12 -> 341.9136
B32: Montant disponible | H32: =H28-H29-H31-H30 -> 109897.04 | I32: =H32+H31 -> 114000 | K32: =K28-K29-K31-K30 -> 9158.0864 | L32: =K32+K31 -> 9500
C35: grille des taux charges patronales en fonction du montant disponible | G35: MAJ au 13/03/25 avec AF et maladie modifié (smic 31/12/2023)
M36: Montant disponible : | N36: =+K32 -> 9158.0864
A37: MT DISPONIBLE | C37: montant disponible | E37: brut MAJ | F37: Mtt ch pat Simul MAJ | G37: charges patronales | H37: taux charges patronales | I37: Salaire net Simul MAJ | J37: salaire net | K37: taux charges salariales | N37: Patronal | O37: Salarial
M38: Taux de charge calculé : | N38: =IF($N$36<=$C$39,H39,IF($N$36<=$C$40,H39,IF($N$36<=$C$41,H40,IF($N$36<=$C$42,H41,IF($N$36<=$C$43,H42,IF($N$36<=$C$44,H43,IF($N$36<=$C$45,H44,IF($N$36<=$C$46,H45,IF($N$36<=$C$47,H46,IF($N$36<=$C$48,H47,IF($N$36<=$C$49,H48,IF($N$36<=$C$50,H49,IF($N$36<=$C$51,H50,IF($N$36<$C$52,H51,IF($N$36<=$C$53,H52,IF($N$36<=$C$54,H53,IF($N$36<=$C$55,H54,IF($N$36<=$C$56,H55,IF($N$36<=$C$57,H56,IF($N$36<=$C$58,H57,IF($N$36<=$C$59,H58,IF($N$36<=$C$60,H59,IF($N$36<=$C$61,H60,IF($N$36<=$C$62,H61,IF($N$36<=$C$63,H62,IF($N$36<=$C$64,H63,IF($N$36<=$C$65,H64,IF($N$36<=$C$66,H65,IF($N$36<=$C$67,H66,IF($N$36<=$C$68,H67,IF($N$36<=$C$69,H68,IF($N$36<=$C$70,H69,IF($N$36<=$C$71,H70,IF($N$36<=$C$72,H71,IF($N$36<=$C$73,H72,IF($N$36<=$C$74,H73,IF($N$36<=$C$75,H74,IF($N$36<=$C$76,H75,H76)))))))))))))))))))))))))))))))))))))) -> 0.46686311 | O38: =IF($N$36<=$C$39,K39,IF($N$36<=$C$40,K39,IF($N$36<=$C$41,K40,IF($N$36<=$C$42,K41,IF($N$36<=$C$43,K42,IF($N$36<=$C$44,K43,IF($N$36<=$C$45,K44,IF($N$36<=$C$46,K45,IF($N$36<=$C$47,K46,IF($N$36<=$C$48,K47,IF($N$36<=$C$49,K48,IF($N$36<=$C$50,K49,IF($N$36<=$C$51,K50,IF($N$36<$C$52,K51,IF($N$36<=$C$53,K52,IF($N$36<=$C$54,K53,IF($N$36<=$C$55,K54,IF($N$36<=$C$56,K55,IF($N$36<=$C$57,K56,IF($N$36<=$C$58,K57,IF($N$36<=$K$59,K58,IF($N$36<=$C$60,K59,IF($N$36<=$C$61,K60,IF($N$36<=$C$62,K61,IF($N$36<=$C$63,K62,IF($N$36<=$C$64,K63,IF($N$36<=$C$65,K64,IF($N$36<=$C$66,K65,IF($N$36<=$C$67,K66,IF($N$36<=$C$68,K67,IF($N$36<=$C$69,K68,IF($N$36<=$C$70,K69,IF($N$36<=$C$71,K70,IF($N$36<=$C$72,K71,IF($N$36<=$C$73,K72,IF($N$36<=$C$74,K73,IF($N$36<=$C$75,K74,IF($N$36<=$C$76,K75,K76)))))))))))))))))))))))))))))))))))))) -> 0.2356252
C39: 5000 | E39: 3666.85 | F39: 1333.15 | G39: =IF($E$15="non",F39+($H$11*($H$12*$H$13)),F39+($H$11*($H$12*$H$13))+($H$16*($H$15*$H$18)+((($H$16*($H$15*$H$18)*8/100))))) -> 1501.3625 | H39: =G39/E39 -> 0.40944203 | I39: 2896.27 | J39: =IF($E$15="non",I39-(($H$12*$H$13)*$H$11),I39-(($H$12*$H$13)*$H$11)-($H$16*($H$15*$H$17))-((($H$16*($H$15*$H$17)*9.7/100)))) -> 2727.5571 | K39: =1-(J39/E39) -> 0.25615799 | S39: 589.35
C40: 5250 | E40: 3850.21 | F40: 1399.79 | G40: =IF($E$15="non",F40+($H$11*($H$12*$H$13)),F40+($H$11*($H$12*$H$13))+($H$16*($H$15*$H$18)+((($H$16*($H$15*$H$18)*8/100))))) -> 1568.0025 | H40: =G40/E40 -> 0.40725116 | I40: 3041.12 | J40: =IF($E$15="non",I40-(($H$12*$H$13)*$H$11),I40-(($H$12*$H$13)*$H$11)-($H$16*($H$15*$H$17))-((($H$16*($H$15*$H$17)*9.7/100)))) -> 2872.4071 | K40: =1-(J40/E40) -> 0.25396094 | S40: 752.01 | T40: =+S40-S39 -> 162.66
A41: < 2,25 smic | C41: 5368.71 | E41: 3931.28 | F41: 1437.43 | G41: =IF($E$15="non",F41+($H$11*($H$12*$H$13)),F41+($H$11*($H$12*$H$13))+($H$16*($H$15*$H$18)+((($H$16*($H$15*$H$18)*8/100))))) -> 1605.6425 | H41: =G41/E41 -> 0.40842741 | I41: 3099.65 | J41: =IF($E$15="non",I41-(($H$12*$H$13)*$H$11),I41-(($H$12*$H$13)*$H$11)-($H$16*($H$15*$H$17))-((($H$16*($H$15*$H$17)*9.7/100)))) -> 2930.9371 | K41: =1-(J41/E41) -> 0.25445731 | M41: Majoration du taux patronal maladie de 6% à partir de 3931,29 brut | S41: 919.97 | T41: =+S41-S40 -> 167.96
A42: >2,25smic (6% mal) | C42: 5604.6 | E42: 3931.29 | F42: 1600.75 | G42: =IF($E$15="non",F42+($H$11*($H$12*$H$13)),F42+($H$11*($H$12*$H$13))+($H$16*($H$15*$H$18)+((($H$16*($H$15*$H$18)*8/100))))) -> 1768.9625 | H42: =G42/E42 -> 0.44996998 | I42: 3099.66 | J42: =IF($E$15="non",I42-(($H$12*$H$13)*$H$11),I42-(($H$12*$H$13)*$H$11)-($H$16*($H$15*$H$17))-((($H$16*($H$15*$H$17)*9.7/100)))) -> 2930.9471 | K42: =1-(J42/E42) -> 0.25445666 | S42: 1087.9 | T42: =+S42-S41 -> 167.93
C43: 5750 | E43: 4033.98 | F43: 1716.02 | G43: =IF($E$15="non",F43+($H$11*($H$12*$H$13)),F43+($H$11*($H$12*$H$13))+($H$16*($H$15*$H$18)+((($H$16*($H$15*$H$18)*8/100))))) -> 1884.2325 | H43: =G43/E43 -> 0.46709019 | I43: 3181.19 | J43: =IF($E$15="non",I43-(($H$12*$H$13)*$H$11),I43-(($H$12*$H$13)*$H$11)-($H$16*($H$15*$H$17))-((($H$16*($H$15*$H$17)*9.7/100)))) -> 3012.4771 | K43: =1-(J43/E43) -> 0.25322459 | S43: 1240.9
C44: 6000 | E44: 4210.58 | F44: 1789.42 | G44: =IF($E$15="non",F44+($H$11*($H$12*$H$13)),F44+($H$11*($H$12*$H$13))+($H$16*($H$15*$H$18)+((($H$16*($H$15*$H$18)*8/100))))) -> 1957.6325 | H44: =G44/E44 -> 0.46493179 | I44: 3321.45 | J44: =IF($E$15="non",I44-(($H$12*$H$13)*$H$11),I44-(($H$12*$H$13)*$H$11)-($H$16*($H$15*$H$17))-((($H$16*($H$15*$H$17)*9.7/100)))) -> 3152.7371 | K44: =1-(J44/E44) -> 0.25123449 | S44: 1240.91
...

Sheet calcul
B1: nom | C1: ='a remplir'!C1 -> Consultant Christian
B2: ='a remplir'!B3:C3 -> mois | C2: ='a remplir'!C3 -> 0
B4: Nombre de jours travaillés | F4: ='a remplir'!H5 -> 120 | I4: repas | J4: km | K4: autres frais | L4: total | M4: frais refacturés aux clients
B5: Nombre de jours potentiel dans le mois | F5: ='a remplir'!H6 -> 228 | H5: montant | I5: ='a remplir'!J6 -> 0 | J5: ='a remplir'!K6 -> 34.19136 | K5: ='a remplir'!L6 -> 0 | M5: ='a remplir'!M6 -> 0
B6: =+'a remplir'!B8 -> salaire de base
B8: TJM | F8: ='a remplir'!H20 -> 1000
B9: Total mensuel | F9: =F4*F8 -> 120000
C10: -Frais refacturés aux clients | F10: ='a remplir'!H27 -> 0
E11: total | F11: =F10+F9 -> 120000
C12: -Frais de gestion | E12: ='a remplir'!H21 -> 0.05 | F12: =(F9+F10)*E12 -> 6000
C13: -Frais d intermediation | F13: ='a remplir'!H30 -> 0
C14: - Frais de fonctionnement | F14: =L14+M14 -> 4102.9632 | I14: =I5*F5 -> 0 | J14: =J5*F4 -> 4102.9632 | K14: =K5 -> 0 | L14: =J14+I14+K14 -> 4102.9632 | M14: =M5 -> 0
B15: Montant disponible | F15: =F11-F12-F14-F13 -> 109897.04 | H15: =F14+F15 -> 114000
B17: Selon BS de simulation : | E17: base mois entier | F17: =C2 -> 0
C18: Salaire de base : | E18: ='a remplir'!H8 -> 2374 | F18: =E18*12 -> 28488
C19: Prime d'apport d'affaires | E19: =E18*0.05 -> 118.7 | F19: =F18*0.05 -> 1424.4
C20: Réserve financière (10%) | E20: =E18*0.1 -> 237.4 | F20: =F18*0.1 -> 2848.8
C21: CP (10 %) | E21: =(E18+E19+E20)*0.1 -> 273.01 | F21: =(F18+F19+F20)*0.1 -> 3276.12
C22: TOTAL BRUT | E22: =SUM(E18:E21) -> 3003.11 | F22: =SUM(F18:F21) -> 36037.32 | I22: taux
B23: + charges patronales | E23: =F23/12 -> 2914.7728 | F23: =L30*I23 -> 34977.274 | I23: ='a remplir'!N38 -> 0.46686311
B24: = cout global | E24: =F24/12 -> 5917.8828 | F24: =F23+F22 -> 71014.594
B26: Brut = | E26: =F15/(1+I23) -> 74919.763
B27: Complément de rémunération = | E27: =E26-F22 -> 38882.443
B28: Décomposé en :
C29: =E27/115.5*100 -> 33664.453 | D29: Complément de rémunération | I29: TOTAL RAJOUT | J29: rajout ind cp | L29: TOTAL BRUT
C30: =E27/115.5*5 -> 1683.2226 | D30: Complément de prime d'apport d'affaires | I30: =C29+C30 -> 35347.675 | J30: =C31 -> 3534.7675 | L30: =+I30+F22+C31 -> 74919.763
C31: =(C29+C30)*10/100 -> 3534.7675 | D31: Complément d'indemnité CP
A33: 2 | D33: Simulation bulletin avec réserve et indemnités cp payés | G33: ='a remplir'!C1 -> Consultant Christian
F34: estimation annuelle (jours facturés) : | G34: estimation mensuelle (jours facturés) :
F35: 228 | G35: ='a remplir'!H9 -> 10
H36: charges patronales :
C37: Salaire de base | F37: =F18 -> 28488 | G37: =(F37/12)*'a remplir'!H7/5 -> 2374
C38: Prime d'apport d'affaires | F38: =C30+F19 -> 3107.6226 | G38: =(F38/12)*'a remplir'!H7/5 -> 258.96855
C39: Réserve financière (10%) | F39: =F20 -> 2848.8 | G39: =(F39/12)*'a remplir'!H7/5 -> 237.4
C40: Complément de rémunération | F40: =C29 -> 33664.453 | G40: =(F40/12)*'a remplir'!H7/5 -> 2805.3711
C41: Indemnité congés payés | F41: =C31+F21 -> 6810.8875 | G41: =(F41/12)*'a remplir'!H7/5 -> 567.57396
D42: brut | F42: =SUM(F37:F41) -> 74919.763 | G42: =(F42/12)*'a remplir'!H7/5 -> 6243.3136
C44: charges salariales : | D44: taux : | E44: ='a remplir'!O38 -> 0.2356252 | F44: =F42*E44 -> 17652.984 | G44: =(F44/12)*'a remplir'!H7/5 -> 1471.082 | H44: =F42*I23 -> 34977.274
D46: frais : | F46: =F14 -> 4102.9632 | G46: =(F46/12)*'a remplir'!$H7/5 -> 341.9136
H47: coût global annuel :
...

Sheet Note
A2: dans l'onglet calcul, 3 simulations sont faites
B4: simulation bulletin avec reserve et cp payé mensuellement | H4: le salarié perçoit la reserve et les cp tous les mois
B6: simulation bulletin sans reserve et cp payé mensuellement | H6: la réserve n'est pas versée au salarié, (le montant de la réserve mis sur le compte activité est égal à la réserve + 10% au titre des cp + charges patronales
B8: simulation bulletin sans reserve sans congé | H8: la réserve et les cp ne sont pas versés tous les mois,
H9: le montant de la réserve mis sur le compte activité est égal à la réserve + 10% au titre des cp + charges patronales
H10: le montant des cp est égal à 10% du salaire (or réserve) + charges patronales, Ils seront versés au salarié à chaque prise de cp (sans anticipation) il s'agit des cp N-1
A11: temps incomplet
A12: Il est appliqué sur les salaires bruts supérieurs à 3,5 fois le smic (5388,03 pour un temps plein) une majoration de 1,8% de charges patronales
A13: Lorsque le salaire est au dessus de 5388,09 brut (ou 7876,57 montant disponible) ce taux est appliqué automatiquement.
A14: Par contre si le mois n'est pas complet et si le salaire passe en dessous des 5388,03 (ou 7779,56montant disponible) du fait de la proratsation de l'absence, il faut rajouter 1,8% au taux de charges patronales

Sheet IK
Q2: Barème voiture thermique
G4: Voiture THERMIQUE
F5: CV | G5: De 0 à 5 000 Kms | H5: De 5 001 à 20 000 Kms | I5: Plus de 20 000 Kms
F6: 3 | G6: =0.529*G67 -> 47.3984 | H6: (0,316 x km) + 1 065 | I6: 0,37 x km
F7: 4 | G7: =0.606*G67 -> 54.2976 | H7: (0,340 x km) + 1 330 | I7: 0,407 x km
F8: 5 | G8: =0.636*G67 -> 56.9856 | H8: (0,357 x km) + 1 395 | I8: 0,427 x km
F9: 6 | G9: =0.665*G67 -> 59.584 | H9: (0,374 x km) + 1 457 | I9: 0,447 x km
F10: 7 et plus | G10: =0.697*G67 -> 62.4512 | H10: (0,394 x km) + 1 515 | I10: 0,470 x km
Q22: Barème DEUX ROUES
G23: DEUX-ROUES
F24: CV | G24: De 0 à 3 000 Kms | H24: De 3 001 à 6 000 Kms | I24: Plus de 6 000 Kms
F25: 1 ou 2 | G25: =0.395*G67 -> 35.392 | H25: (0,099 x km) + 891 | I25: 0,248 x km
F26: 3,4 ou 5 | G26: =0.468*G67 -> 41.9328 | H26: (0,082 x km) + 1 158 | I26: 0,275 x km
F27: 5 et plus | G27: =0.606*G67 -> 54.2976 | H27: (0,079x km) + 1 583 | I27: 0,343 x km
H38: VOITURE ELECTRIQUE
F39: CV | G39: De 0 à 5 000 Kms | H39: De 5 001 à 20 000 Kms | I39: Plus de 20 000 Kms
F40: 3 | G40: =0.635*G67 -> 56.896 | H40: (0,380 x km) + 1 278 | I40: 0,444 x km
F41: 4 | G41: =0.727*G67 -> 65.1392 | H41: (0,408 x km) + 1 596 | I41: 0,488 x km
F42: 5 | G42: =0.763*G67 -> 68.3648 | H42: (0,428 x km) + 1 674 | I42: 0,512 x km
F43: 6 | G43: =0.798*G67 -> 71.5008 | H43: (0,449 x km) + 1 748 | I43: 0,536 x km
F44: 7 et plus | G44: =0.836*G67 -> 74.9056 | H44: (0,472 x km) + 1 818 | I44: 0,564 x km
D52: 1 | H52: Voiture électrique
D53: 2 | H53: Voiture Thermique
D54: 3 | H54: Deux-Roues
D55: 4
D56: 5
D57: 6
D58: 7 et plus
F65: Type de Véhicule | G65: =+'a remplir'!Q21 -> Voiture Thermique
F66: Puissance FISCALE | G66: =+'a remplir'!Q22 -> 5
F67: Distance par jour Aller-retour en KM | G67: =+'a remplir'!Q23 -> 89.6
F68: Nombre de déplacements par semaine | G68: =+'a remplir'!Q24 -> 3
F69: Distance Total Annuelle | G69: =+(G67*G68)*4*12 -> 12902.4
F71: Indemnités Kilométriques Journalière | G71: =IF(AND(G65="Voiture Thermique",G66=3),G6,"")&IF(AND(G65="Voiture Thermique",G66=4),G7,"")&IF(AND(G65="Voiture Thermique",G66=5),G8,"")&IF(AND(G65="Voiture Thermique",G66=6),G9,"")&IF(AND(G65="Voiture Thermique",G66="7 et plus"),G9,"")&IF(AND(G65="Voiture électrique",G66=3),G40,"")&IF(AND(G65="Voiture électrique",G66=4),G41,"")&IF(AND(G65="Voiture électrique",G66=5),G42,"")&IF(AND(G65="Voiture électrique",G66=6),G43,"")&IF(AND(G65="Voiture électrique",G66="7 et plus"),G44,"")&IF(AND(G65="Deux-Roues",G66=1),G25,"")&IF(AND(G65="Deux-Roues",G66=2),G25,"")&IF(AND(G65="Deux-Roues",G66=3),G26,"")&IF(AND(G65="Deux-Roues",G66=4),G26,"")&IF(AND(G65="Deux-Roues",G66=5),G26,"")&IF(AND(G65="Deux-Roues",G66=6),G27,"") -> 56,9856
F72: IK Finale | G72: =+IF('a remplir'!Q21<>0,(G71*(G68/5)),0) -> 34.19136

Sheet NE PAS TOUCHER
